2024-05-19 03:39:16,321 - app - ERROR - Error in index route: String or int arguments are only possible when a DataFrame or an array is provided in the `data_frame` argument. No DataFrame was provided, but argument 'lat' is of type str or int.
2024-05-19 03:44:33,121 - app - ERROR - Error in index route: 'NoneType' object has no attribute 'predict'
2024-05-19 03:47:07,966 - app - ERROR - Error in index route: 'NoneType' object has no attribute 'predict'
2024-05-19 03:49:47,807 - app - ERROR - Error in index route: 'NoneType' object has no attribute 'predict'
2024-05-19 17:06:08,384 - app - ERROR - Error in index route: Value of 'size' is not the name of a column in 'data_frame'. Expected one of ['datetime', 'averagevehiclespeed', 'traveltime', 'traffic', 'lat', 'lon'] but received: size
2024-05-20 08:39:40,241 - app - ERROR - Error creating figure: Value of 'lat' is not the name of a column in 'data_frame'. Expected one of ['datetime', 'predefinedlocationreference', 'averagevehiclespeed', 'traveltime', 'traveltimereliability', 'trafficstatus', 'vehicleprobemeasurement', 'geo_point_2d', 'geo_shape', 'gml_id', 'id_rva_troncon_fcd_v1_1', 'hierarchie', 'hierarchie_dv', 'denomination', 'insee', 'sens_circule', 'vitesse_maxi'] but received: lat
2024-05-20 08:39:40,244 - app - ERROR - Error in index route: Value of 'lat' is not the name of a column in 'data_frame'. Expected one of ['datetime', 'predefinedlocationreference', 'averagevehiclespeed', 'traveltime', 'traveltimereliability', 'trafficstatus', 'vehicleprobemeasurement', 'geo_point_2d', 'geo_shape', 'gml_id', 'id_rva_troncon_fcd_v1_1', 'hierarchie', 'hierarchie_dv', 'denomination', 'insee', 'sens_circule', 'vitesse_maxi'] but received: lat
2024-05-20 08:42:01,872 - app - ERROR - Error creating figure: Value of 'lat' is not the name of a column in 'data_frame'. Expected one of ['datetime', 'predefinedlocationreference', 'averagevehiclespeed', 'traveltime', 'traveltimereliability', 'trafficstatus', 'vehicleprobemeasurement', 'geo_point_2d', 'geo_shape', 'gml_id', 'id_rva_troncon_fcd_v1_1', 'hierarchie', 'hierarchie_dv', 'denomination', 'insee', 'sens_circule', 'vitesse_maxi'] but received: lat
2024-05-20 08:42:01,873 - app - ERROR - Error in index route: Value of 'lat' is not the name of a column in 'data_frame'. Expected one of ['datetime', 'predefinedlocationreference', 'averagevehiclespeed', 'traveltime', 'traveltimereliability', 'trafficstatus', 'vehicleprobemeasurement', 'geo_point_2d', 'geo_shape', 'gml_id', 'id_rva_troncon_fcd_v1_1', 'hierarchie', 'hierarchie_dv', 'denomination', 'insee', 'sens_circule', 'vitesse_maxi'] but received: lat
2024-05-20 09:05:46,216 - app - ERROR - Error creating figure: scatter() got an unexpected keyword argument 'lat'
2024-05-20 09:05:46,220 - app - ERROR - Error in index route: scatter() got an unexpected keyword argument 'lat'
2024-05-20 09:08:44,302 - app - ERROR - Error creating figure: scatter() got an unexpected keyword argument 'lat'
2024-05-20 09:08:44,303 - app - ERROR - Error in index route: scatter() got an unexpected keyword argument 'lat'
2024-05-20 09:08:53,401 - app - ERROR - Error creating figure: scatter() got an unexpected keyword argument 'lat'
2024-05-20 09:08:53,402 - app - ERROR - Error in index route: scatter() got an unexpected keyword argument 'lat'
2024-05-20 09:09:48,512 - app - ERROR - Error creating figure: scatter() got an unexpected keyword argument 'lat'
2024-05-20 09:09:48,513 - app - ERROR - Error in index route: scatter() got an unexpected keyword argument 'lat'
2024-05-20 09:13:30,798 - app - ERROR - Error creating figure: name 'go' is not defined
2024-05-20 09:13:30,801 - app - ERROR - Error in index route: name 'go' is not defined
2024-05-20 09:13:56,179 - app - ERROR - Error creating figure: name 'go' is not defined
2024-05-20 09:13:56,180 - app - ERROR - Error in index route: name 'go' is not defined
2024-05-20 10:21:37,294 - app - INFO - Fetching data...
2024-05-20 10:22:16,292 - app - INFO - Fetching data...
2024-05-20 10:22:46,294 - app - INFO - Fetching data...
2024-05-20 10:23:06,327 - app - INFO - Fetching data...
2024-05-20 10:24:58,732 - app - INFO - Fetching data...
2024-05-20 10:25:17,711 - app - INFO - Fetching data...
2024-05-20 10:35:48,657 - app - INFO - Fetching data...
2024-05-20 10:39:17,262 - app - INFO - Fetching data...
2024-05-20 10:43:06,049 - app - INFO - Fetching data...
2024-05-20 10:43:12,659 - app - ERROR - Error fetching data: Expecting ',' delimiter: line 1 column 1254815 (char 1254814)
2024-05-20 10:43:15,176 - app - ERROR - Error in index route: Data is empty
2024-05-20 10:44:29,778 - app - INFO - Fetching data...
2024-05-20 10:45:11,338 - app - INFO - Fetching data...
2024-05-20 10:45:16,053 - app - ERROR - Error fetching data: Expecting ',' delimiter: line 1 column 288182 (char 288181)
2024-05-20 10:45:19,081 - app - ERROR - Error in index route: Data is empty
2024-05-20 10:45:37,010 - app - INFO - Fetching data...
2024-05-20 10:46:54,176 - app - INFO - Fetching data...
2024-05-20 10:49:24,972 - app - INFO - Fetching data...
2024-05-20 10:49:46,764 - app - ERROR - Error creating figure: name 'title' is not defined
2024-05-20 10:49:46,776 - app - ERROR - Error in index route: name 'title' is not defined
2024-05-20 10:50:15,085 - app - INFO - Fetching data...
2024-05-20 10:52:25,781 - app - INFO - Fetching data...
2024-05-20 10:54:03,684 - app - INFO - Fetching data...
2024-05-20 10:54:43,627 - app - INFO - Fetching data...
2024-05-20 10:55:11,186 - app - INFO - Fetching data...
2024-05-20 10:55:37,373 - app - INFO - Fetching data...
2024-05-20 10:57:23,823 - app - INFO - Fetching data...
2024-05-20 10:58:28,978 - app - INFO - Fetching data...
2024-05-20 11:15:35,856 - app - INFO - Fetching data...
2024-05-20 11:25:11,188 - app - INFO - Fetching data...
2024-05-20 13:34:28,155 - app - INFO - Fetching data...
2024-05-20 13:34:28,175 - app - ERROR - Error fetching data: HTTPSConnectionPool(host='data.rennesmetropole.fr', port=443): Max retries exceeded with url: /api/explore/v2.1/catalog/datasets/etat-du-trafic-en-temps-reel/exports/json?lang=fr&timezone=Europe%2FBerlin&use_labels=true&delimiter=%3B&apikey=51fc720694959be3dee39ba8e515826ab669377a28f3f79227970508 (Caused by NameResolutionError("<urllib3.connection.HTTPSConnection object at 0x000001D0AC580F50>: Failed to resolve 'data.rennesmetropole.fr' ([Errno 11001] getaddrinfo failed)"))
